Workbook

Sheet Découpe
A1: Journée | B1: Produit | C1: Quantité | D1: Rejet-Démarage | E1: Rejet qualité | F1: Panne | G1: Arrêts mineurs | H1: Nettoyage | I1: Réglage dérive machine | J1: Inspection machine | K1: changement d'outil | L1: Déplacement/Manutention | M1: Remplacement préventif | N1: Lubrification | O1: pause | P1: TO | Q1: TR | R1: tfb | S1: tn | T1: tu | U1: TD | V1: TQ | W1: TP | X1: TRS
A2: 1 | B2: P1 | C2: 1841 | D2: 18 | E2: 14 | F2: 112 | G2: 29 | H2: 15 | I2: 15 | J2: 12 | K2: 30 | L2: 32 | N2: 16 | O2: =37500/250 -> 150 | P2: =4000*60/250 -> 960 | Q2: =P2-H2-J2-M2-N2-O2 -> 767 | R2: =Q2-F2-G2-I2-K2-L2 -> 549 | S2: =C2*0.26 -> 478.66 | T2: =(C2-D2-E2)*0.26 -> 470.34 | U2: =R2/Q2 -> 0.71577575 | V2: =(C2-D2-E2)/C2 -> 0.98261814 | W2: =S2/R2 -> 0.87187614 | X2: =U2*V2*W2 -> 0.61322034
A3: 2 | B3: P3 | C3: 1755 | D3: 18 | E3: 28 | F3: 145 | G3: 29 | H3: 16 | I3: 18 | J3: 10 | K3: 30 | L3: 32 | N3: 17 | O3: =37500/250 -> 150 | P3: =4000*60/250 -> 960 | Q3: =P3-H3-J3-M3-N3-O3 -> 767 | R3: =Q3-F3-G3-I3-K3-L3 -> 513 | S3: =C3*0.26 -> 456.3 | T3: =(C3-D3-E3)*0.26 -> 444.34 | U3: =R3/Q3 -> 0.66883963 | V3: =(C3-D3-E3)/C3 -> 0.97378917 | W3: =S3/R3 -> 0.88947368 | X3: =U3*V3*W3 -> 0.57932203
A4: 3 | B4: P2 | C4: 1739 | D4: 28 | E4: 29 | F4: 110 | G4: 24 | H4: 18 | I4: 11 | J4: 8 | K4: 32 | L4: 33 | N4: 17 | O4: =37500/250 -> 150 | P4: =4000*60/250 -> 960 | Q4: =P4-H4-J4-M4-N4-O4 -> 767 | R4: =Q4-F4-G4-I4-K4-L4 -> 557 | S4: =C4*0.26 -> 452.14 | T4: =(C4-D4-E4)*0.26 -> 437.32 | U4: =R4/Q4 -> 0.726206 | V4: =(C4-D4-E4)/C4 -> 0.96722254 | W4: =S4/R4 -> 0.81174147 | X4: =U4*V4*W4 -> 0.57016949
A5: 4 | B5: P4 | C5: 1802 | D5: 14 | E5: 21 | F5: 107 | G5: 30 | H5: 16 | I5: 21 | J5: 8 | K5: 28 | L5: 35 | N5: 17 | O5: =37500/250 -> 150 | P5: =4000*60/250 -> 960 | Q5: =P5-H5-J5-M5-N5-O5 -> 769 | R5: =Q5-F5-G5-I5-K5-L5 -> 548 | S5: =C5*0.26 -> 468.52 | T5: =(C5-D5-E5)*0.26 -> 459.42 | U5: =R5/Q5 -> 0.71261378 | V5: =(C5-D5-E5)/C5 -> 0.98057714 | W5: =S5/R5 -> 0.8549635 | X5: =U5*V5*W5 -> 0.59742523
A6: 5 | B6: P1 | C6: 1716 | D6: 23 | E6: 23 | F6: 134 | G6: 41 | H6: 17 | I6: 13 | J6: 11 | K6: 31 | L6: 37 | N6: 14 | O6: =37500/250 -> 150 | P6: =4000*60/250 -> 960 | Q6: =P6-H6-J6-M6-N6-O6 -> 768 | R6: =Q6-F6-G6-I6-K6-L6 -> 512 | S6: =C6*0.26 -> 446.16 | T6: =(C6-D6-E6)*0.26 -> 434.2 | U6: =R6/Q6 -> 0.66666667 | V6: =(C6-D6-E6)/C6 -> 0.97319347 | W6: =S6/R6 -> 0.87140625 | X6: =U6*V6*W6 -> 0.56536458
A7: 6 | B7: P2 | C7: 1872 | D7: 16 | E7: 40 | F7: 133 | G7: 26 | H7: 18 | I7: 11 | J7: 10 | K7: 31 | L7: 34 | N7: 14 | O7: =37500/250 -> 150 | P7: =4000*60/250 -> 960 | Q7: =P7-H7-J7-M7-N7-O7 -> 768 | R7: =Q7-F7-G7-I7-K7-L7 -> 533 | S7: =C7*0.26 -> 486.72 | T7: =(C7-D7-E7)*0.26 -> 472.16 | U7: =R7/Q7 -> 0.69401042 | V7: =(C7-D7-E7)/C7 -> 0.97008547 | W7: =S7/R7 -> 0.91317073 | X7: =U7*V7*W7 -> 0.61479167
A8: 7 | B8: P2 | C8: 1847 | D8: 14 | E8: 14 | F8: 124 | G8: 17 | H8: 16 | I8: 16 | J8: 8 | L8: 28 | N8: 15 | O8: =37500/250 -> 150 | P8: =4000*60/250 -> 960 | Q8: =P8-H8-J8-M8-N8-O8 -> 771 | R8: =Q8-F8-G8-I8-K8-L8 -> 586 | S8: =C8*0.26 -> 480.22 | T8: =(C8-D8-E8)*0.26 -> 472.94 | U8: =R8/Q8 -> 0.76005188 | V8: =(C8-D8-E8)/C8 -> 0.98484028 | W8: =S8/R8 -> 0.81948805 | X8: =U8*V8*W8 -> 0.61341115
A9: 8 | B9: P4 | C9: 1877 | D9: 10 | E9: 39 | F9: 119 | G9: 25 | H9: 17 | I9: 17 | J9: 9 | K9: 20 | L9: 31 | N9: 17 | O9: =37500/250 -> 150 | P9: =4000*60/250 -> 960 | Q9: =P9-H9-J9-M9-N9-O9 -> 767 | R9: =Q9-F9-G9-I9-K9-L9 -> 555 | S9: =C9*0.26 -> 488.02 | T9: =(C9-D9-E9)*0.26 -> 475.28 | U9: =R9/Q9 -> 0.72359844 | V9: =(C9-D9-E9)/C9 -> 0.97389451 | W9: =S9/R9 -> 0.87931532 | X9: =U9*V9*W9 -> 0.61966102
A10: 9 | B10: P1 | C10: 1788 | D10: 18 | E10: 50 | F10: 140 | G10: 29 | H10: 16 | I10: 14 | J10: 12 | K10: 28 | L10: 29 | N10: 19 | O10: =37500/250 -> 150 | P10: =4000*60/250 -> 960 | Q10: =P10-H10-J10-M10-N10-O10 -> 763 | R10: =Q10-F10-G10-I10-K10-L10 -> 523 | S10: =C10*0.26 -> 464.88 | T10: =(C10-D10-E10)*0.26 -> 447.2 | U10: =R10/Q10 -> 0.68545216 | V10: =(C10-D10-E10)/C10 -> 0.96196868 | W10: =S10/R10 -> 0.88887189 | X10: =U10*V10*W10 -> 0.58610747
A11: 10 | B11: P3 | C11: 1781 | D11: 18 | E11: 43 | F11: 87 | G11: 21 | H11: 20 | I11: 12 | J11: 9 | K11: 15 | L11: 29 | M11: 20 | N11: 15 | O11: =37500/250 -> 150 | P11: =4000*60/250 -> 960 | Q11: =P11-H11-J11-M11-N11-O11 -> 746 | R11: =Q11-F11-G11-I11-K11-L11 -> 582 | S11: =C11*0.26 -> 463.06 | T11: =(C11-D11-E11)*0.26 -> 447.2 | U11: =R11/Q11 -> 0.78016086 | V11: =(C11-D11-E11)/C11 -> 0.96574958 | W11: =S11/R11 -> 0.79563574 | X11: =U11*V11*W11 -> 0.59946381
A12: 11 | B12: P2 | C12: 1872 | D12: 27 | E12: 37 | F12: 118 | G12: 37 | H12: 16 | I12: 14 | J12: 8 | K12: 19 | L12: 25 | N12: 13 | O12: =37500/250 -> 150 | P12: =4000*60/250 -> 960 | Q12: =P12-H12-J12-M12-N12-O12 -> 773 | R12: =Q12-F12-G12-I12-K12-L12 -> 560 | S12: =C12*0.26 -> 486.72 | T12: =(C12-D12-E12)*0.26 -> 470.08 | U12: =R12/Q12 -> 0.72445019 | V12: =(C12-D12-E12)/C12 -> 0.96581197 | W12: =S12/R12 -> 0.86914286 | X12: =U12*V12*W12 -> 0.60812419
A13: 12 | B13: P4 | C13: 1915 | D13: 13 | E13: 50 | F13: 126 | G13: 30 | H13: 16 | I13: 18 | J13: 8 | K13: 23 | L13: 35 | N13: 16 | O13: =37500/250 -> 150 | P13: =4000*60/250 -> 960 | Q13: =P13-H13-J13-M13-N13-O13 -> 770 | R13: =Q13-F13-G13-I13-K13-L13 -> 538 | S13: =C13*0.26 -> 497.9 | T13: =(C13-D13-E13)*0.26 -> 481.52 | U13: =R13/Q13 -> 0.6987013 | V13: =(C13-D13-E13)/C13 -> 0.96710183 | W13: =S13/R13 -> 0.92546468 | X13: =U13*V13*W13 -> 0.62535065
A14: 13 | B14: P2 | C14: 1726 | D14: 12 | E14: 6 | F14: 143 | G14: 37 | H14: 20 | I14: 17 | J14: 6 | K14: 23 | L14: 32 | N14: 15 | O14: =37500/250 -> 150 | P14: =4000*60/250 -> 960 | Q14: =P14-H14-J14-M14-N14-O14 -> 769 | R14: =Q14-F14-G14-I14-K14-L14 -> 517 | S14: =C14*0.26 -> 448.76 | T14: =(C14-D14-E14)*0.26 -> 444.08 | U14: =R14/Q14 -> 0.67230169 | V14: =(C14-D14-E14)/C14 -> 0.98957126 | W14: =S14/R14 -> 0.86800774 | X14: =U14*V14*W14 -> 0.57747724
A15: 14 | B15: P4 | C15: 1861 | D15: 27 | E15: 49 | F15: 118 | G15: 31 | H15: 15 | I15: 17 | J15: 12 | K15: 28 | L15: 27 | N15: 16 | O15: =37500/250 -> 150 | P15: =4000*60/250 -> 960 | Q15: =P15-H15-J15-M15-N15-O15 -> 767 | R15: =Q15-F15-G15-I15-K15-L15 -> 546 | S15: =C15*0.26 -> 483.86 | T15: =(C15-D15-E15)*0.26 -> 464.1 | U15: =R15/Q15 -> 0.71186441 | V15: =(C15-D15-E15)/C15 -> 0.95916174 | W15: =S15/R15 -> 0.88619048 | X15: =U15*V15*W15 -> 0.60508475
A16: 15 | B16: P1 | C16: 1867 | D16: 25 | E16: 47 | F16: 119 | G16: 31 | H16: 20 | I16: 21 | J16: 6 | K16: 30 | L16: 34 | N16: 15 | O16: =37500/250 -> 150 | P16: =4000*60/250 -> 960 | Q16: =P16-H16-J16-M16-N16-O16 -> 769 | R16: =Q16-F16-G16-I16-K16-L16 -> 534 | S16: =C16*0.26 -> 485.42 | T16: =(C16-D16-E16)*0.26 -> 466.7 | U16: =R16/Q16 -> 0.69440832 | V16: =(C16-D16-E16)/C16 -> 0.96143546 | W16: =S16/R16 -> 0.90902622 | X16: =U16*V16*W16 -> 0.60689207
A17: 16 | B17: P3 | C17: 1677 | D17: 26 | E17: 20 | F17: 99 | G17: 31 | H17: 17 | I17: 21 | J17: 13 | K17: 19 | L17: 34 | N17: 15 | O17: =37500/250 -> 150 | P17: =4000*60/250 -> 960 | Q17: =P17-H17-J17-M17-N17-O17 -> 765 | R17: =Q17-F17-G17-I17-K17-L17 -> 561 | S17: =C17*0.26 -> 436.02 | T17: =(C17-D17-E17)*0.26 -> 424.06 | U17: =R17/Q17 -> 0.73333333 | V17: =(C17-D17-E17)/C17 -> 0.97257007 | W17: =S17/R17 -> 0.77721925 | X17: =U17*V17*W17 -> 0.5543268
A18: 17 | B18: P2 | C18: 1725 | D18: 30 | E18: 18 | F18: 119 | G18: 32 | H18: 17 | I18: 18 | J18: 8 | K18: 33 | L18: 33 | N18: 16 | O18: =37500/250 -> 150 | P18: =4000*60/250 -> 960 | Q18: =P18-H18-J18-M18-N18-O18 -> 769 | R18: =Q18-F18-G18-I18-K18-L18 -> 534 | S18: =C18*0.26 -> 448.5 | T18: =(C18-D18-E18)*0.26 -> 436.02 | U18: =R18/Q18 -> 0.69440832 | V18: =(C18-D18-E18)/C18 -> 0.97217391 | W18: =S18/R18 -> 0.83988764 | X18: =U18*V18*W18 -> 0.5669961
A19: 18 | B19: P4 | C19: 1888 | D19: 20 | E19: 50 | F19: 108 | G19: 29 | H19: 16 | I19: 27 | J19: 11 | K19: 30 | L19: 32 | N19: 19 | O19: =37500/250 -> 150 | P19: =4000*60/250 -> 960 | Q19: =P19-H19-J19-M19-N19-O19 -> 764 | R19: =Q19-F19-G19-I19-K19-L19 -> 538 | S19: =C19*0.26 -> 490.88 | T19: =(C19-D19-E19)*0.26 -> 472.68 | U19: =R19/Q19 -> 0.70418848 | V19: =(C19-D19-E19)/C19 -> 0.96292373 | W19: =S19/R19 -> 0.91241636 | X19: =U19*V19*W19 -> 0.6186911
A20: 19 | B20: P3 | C20: 1831 | D20: 11 | E20: 13 | F20: 147 | G20: 40 | H20: 18 | I20: 21 | J20: 11 | K20: 17 | L20: 33 | N20: 17 | O20: =37500/250 -> 150 | P20: =4000*60/250 -> 960 | Q20: =P20-H20-J20-M20-N20-O20 -> 764 | R20: =Q20-F20-G20-I20-K20-L20 -> 506 | S20: =C20*0.26 -> 476.06 | T20: =(C20-D20-E20)*0.26 -> 469.82 | U20: =R20/Q20 -> 0.66230366 | V20: =(C20-D20-E20)/C20 -> 0.98689241 | W20: =S20/R20 -> 0.94083004 | X20: =U20*V20*W20 -> 0.61494764
A21: 20 | B21: P2 | C21: 1827 | D21: 11 | E21: 48 | F21: 133 | G21: 20 | H21: 16 | I21: 22 | J21: 7 | K21: 28 | L21: 26 | M21: 25 | N21: 19 | O21: =37500/250 -> 150 | P21: =4000*60/250 -> 960 | Q21: =P21-H21-J21-M21-N21-O21 -> 743 | R21: =Q21-F21-G21-I21-K21-L21 -> 514 | S21: =C21*0.26 -> 475.02 | T21: =(C21-D21-E21)*0.26 -> 459.68 | U21: =R21/Q21 -> 0.69179004 | V21: =(C21-D21-E21)/C21 -> 0.96770662 | W21: =S21/R21 -> 0.92416342 | X21: =U21*V21*W21 -> 0.61868102
A22: 21 | B22: P1 | C22: 1878 | D22: 19 | E22: 17 | F22: 112 | G22: 27 | H22: 19 | I22: 22 | J22: 11 | K22: 25 | L22: 27 | N22: 15 | O22: =37500/250 -> 150 | P22: =4000*60/250 -> 960 | Q22: =P22-H22-J22-M22-N22-O22 -> 765 | R22: =Q22-F22-G22-I22-K22-L22 -> 552 | S22: =C22*0.26 -> 488.28 | T22: =(C22-D22-E22)*0.26 -> 478.92 | U22: =R22/Q22 -> 0.72156863 | V22: =(C22-D22-E22)/C22 -> 0.98083067 | W22: =S22/R22 -> 0.88456522 | X22: =U22*V22*W22 -> 0.62603922
A23: 22 | B23: P3 | C23: 1883 | D23: 10 | E23: 22 | F23: 113 | G23: 37 | H23: 20 | I23: 18 | J23: 10 | K23: 22 | L23: 32 | N23: 14 | O23: =37500/250 -> 150 | P23: =4000*60/250 -> 960 | Q23: =P23-H23-J23-M23-N23-O23 -> 766 | R23: =Q23-F23-G23-I23-K23-L23 -> 544 | S23: =C23*0.26 -> 489.58 | T23: =(C23-D23-E23)*0.26 -> 481.26 | U23: =R23/Q23 -> 0.71018277 | V23: =(C23-D23-E23)/C23 -> 0.98300584 | W23: =S23/R23 -> 0.89996324 | X23: =U23*V23*W23 -> 0.62827676
A24: 23 | B24: P2 | C24: 1792 | D24: 11 | E24: 30 | F24: 136 | G24: 37 | H24: 17 | I24: 18 | J24: 10 | K24: 31 | L24: 33 | N24: 20 | O24: =37500/250 -> 150 | P24: =4000*60/250 -> 960 | Q24: =P24-H24-J24-M24-N24-O24 -> 763 | R24: =Q24-F24-G24-I24-K24-L24 -> 508 | S24: =C24*0.26 -> 465.92 | T24: =(C24-D24-E24)*0.26 -> 455.26 | U24: =R24/Q24 -> 0.66579292 | V24: =(C24-D24-E24)/C24 -> 0.97712054 | W24: =S24/R24 -> 0.91716535 | X24: =U24*V24*W24 -> 0.59667104
A25: 24 | B25: P4 | C25: 1763 | D25: 19 | E25: 35 | F25: 134 | G25: 27 | H25: 17 | I25: 26 | J25: 9 | K25: 25 | L25: 36 | N25: 18 | O25: =37500/250 -> 150 | P25: =4000*60/250 -> 960 | Q25: =P25-H25-J25-M25-N25-O25 -> 766 | R25: =Q25-F25-G25-I25-K25-L25 -> 518 | S25: =C25*0.26 -> 458.38 | T25: =(C25-D25-E25)*0.26 -> 444.34 | U25: =R25/Q25 -> 0.67624021 | V25: =(C25-D25-E25)/C25 -> 0.96937039 | W25: =S25/R25 -> 0.88490347 | X25: =U25*V25*W25 -> 0.58007833
A26: 25 | B26: P3 | C26: 1863 | D26: 14 | E26: 50 | F26: 129 | G26: 36 | H26: 15 | I26: 30 | J26: 11 | K26: 17 | L26: 35 | N26: 18 | O26: =37500/250 -> 150 | P26: =4000*60/250 -> 960 | Q26: =P26-H26-J26-M26-N26-O26 -> 766 | R26: =Q26-F26-G26-I26-K26-L26 -> 519 | S26: =C26*0.26 -> 484.38 | T26: =(C26-D26-E26)*0.26 -> 467.74 | U26: =R26/Q26 -> 0.67754569 | V26: =(C26-D26-E26)/C26 -> 0.96564681 | W26: =S26/R26 -> 0.9332948 | X26: =U26*V26*W26 -> 0.61062663
A27: 26 | B27: P2 | C27: 1791 | D27: 30 | E27: 20 | F27: 113 | G27: 32 | H27: 15 | I27: 30 | J27: 10 | K27: 18 | L27: 33 | N27: 16 | O27: =37500/250 -> 150 | P27: =4000*60/250 -> 960 | Q27: =P27-H27-J27-M27-N27-O27 -> 769 | R27: =Q27-F27-G27-I27-K27-L27 -> 543 | S27: =C27*0.26 -> 465.66 | T27: =(C27-D27-E27)*0.26 -> 452.66 | U27: =R27/Q27 -> 0.70611183 | V27: =(C27-D27-E27)/C27 -> 0.97208264 | W27: =S27/R27 -> 0.85756906 | X27: =U27*V27*W27 -> 0.58863459
A28: 27 | B28: P4 | C28: 1672 | D28: 20 | E28: 24 | F28: 156 | G28: 42 | H28: 19 | I28: 20 | J28: 8 | K28: 30 | L28: 34 | N28: 14 | O28: =37500/250 -> 150 | P28: =4000*60/250 -> 960 | Q28: =P28-H28-J28-M28-N28-O28 -> 769 | R28: =Q28-F28-G28-I28-K28-L28 -> 487 | S28: =C28*0.26 -> 434.72 | T28: =(C28-D28-E28)*0.26 -> 423.28 | U28: =R28/Q28 -> 0.63328999 | V28: =(C28-D28-E28)/C28 -> 0.97368421 | W28: =S28/R28 -> 0.89264887 | X28: =U28*V28*W28 -> 0.55042913
A29: 28 | B29: P4 | C29: 1716 | D29: 21 | E29: 29 | F29: 115 | G29: 27 | H29: 18 | I29: 20 | J29: 12 | L29: 38 | N29: 15 | O29: =37500/250 -> 150 | P29: =4000*60/250 -> 960 | Q29: =P29-H29-J29-M29-N29-O29 -> 765 | R29: =Q29-F29-G29-I29-K29-L29 -> 565 | S29: =C29*0.26 -> 446.16 | T29: =(C29-D29-E29)*0.26 -> 433.16 | U29: =R29/Q29 -> 0.73856209 | V29: =(C29-D29-E29)/C29 -> 0.97086247 | W29: =S29/R29 -> 0.78966372 | X29: =U29*V29*W29 -> 0.56622222
A30: 29 | B30: P3 | C30: 1832 | D30: 10 | E30: 35 | F30: 121 | G30: 34 | H30: 20 | I30: 28 | J30: 8 | K30: 24 | L30: 30 | N30: 17 | O30: =37500/250 -> 150 | P30: =4000*60/250 -> 960 | Q30: =P30-H30-J30-M30-N30-O30 -> 765 | R30: =Q30-F30-G30-I30-K30-L30 -> 528 | S30: =C30*0.26 -> 476.32 | T30: =(C30-D30-E30)*0.26 -> 464.62 | U30: =R30/Q30 -> 0.69019608 | V30: =(C30-D30-E30)/C30 -> 0.97543668 | W30: =S30/R30 -> 0.90212121 | X30: =U30*V30*W30 -> 0.60734641
A31: 30 | B31: P2 | C31: 1837 | D31: 21 | E31: 29 | F31: 117 | G31: 32 | H31: 17 | I31: 29 | J31: 11 | K31: 35 | L31: 28 | M31: 30 | N31: 18 | O31: =37500/250 -> 150 | P31: =4000*60/250 -> 960 | Q31: =P31-H31-J31-M31-N31-O31 -> 734 | R31: =Q31-F31-G31-I31-K31-L31 -> 493 | S31: =C31*0.26 -> 477.62 | T31: =(C31-D31-E31)*0.26 -> 464.62 | U31: =R31/Q31 -> 0.67166213 | V31: =(C31-D31-E31)/C31 -> 0.97278171 | W31: =S31/R31 -> 0.96880325 | X31: =U31*V31*W31 -> 0.63299728
A32: 31 | B32: P1 | C32: 1812 | D32: 24 | E32: 45 | F32: 115 | G32: 29 | H32: 15 | I32: 23 | J32: 12 | K32: 36 | L32: 27 | N32: 17 | O32: =37500/250 -> 150 | P32: =4000*60/250 -> 960 | Q32: =P32-H32-J32-M32-N32-O32 -> 766 | R32: =Q32-F32-G32-I32-K32-L32 -> 536 | S32: =C32*0.26 -> 471.12 | T32: =(C32-D32-E32)*0.26 -> 453.18 | U32: =R32/Q32 -> 0.6997389 | V32: =(C32-D32-E32)/C32 -> 0.96192053 | W32: =S32/R32 -> 0.87895522 | X32: =U32*V32*W32 -> 0.5916188
A33: 32 | B33: P3 | C33: 1701 | D33: 15 | E33: 15 | F33: 134 | G33: 38 | H33: 20 | I33: 22 | J33: 8 | K33: 18 | L33: 36 | N33: 13 | O33: =37500/250 -> 150 | P33: =4000*60/250 -> 960 | Q33: =P33-H33-J33-M33-N33-O33 -> 769 | R33: =Q33-F33-G33-I33-K33-L33 -> 521 | S33: =C33*0.26 -> 442.26 | T33: =(C33-D33-E33)*0.26 -> 434.46 | U33: =R33/Q33 -> 0.67750325 | V33: =(C33-D33-E33)/C33 -> 0.98236332 | W33: =S33/R33 -> 0.84886756 | X33: =U33*V33*W33 -> 0.56496749
A34: 33 | B34: P2 | C34: 1731 | D34: 27 | E34: 30 | F34: 126 | G34: 34 | H34: 20 | I34: 32 | J34: 9 | K34: 31 | L34: 27 | N34: 16 | O34: =37500/250 -> 150 | P34: =4000*60/250 -> 960 | Q34: =P34-H34-J34-M34-N34-O34 -> 765 | R34: =Q34-F34-G34-I34-K34-L34 -> 515 | S34: =C34*0.26 -> 450.06 | T34: =(C34-D34-E34)*0.26 -> 435.24 | U34: =R34/Q34 -> 0.67320261 | V34: =(C34-D34-E34)/C34 -> 0.96707106 | W34: =S34/R34 -> 0.87390291 | X34: =U34*V34*W34 -> 0.56894118
A35: 34 | B35: P2 | C35: 1654 | D35: 25 | E35: 45 | F35: 125 | G35: 27 | H35: 17 | I35: 32 | J35: 10 | L35: 33 | N35: 15 | O35: =37500/250 -> 150 | P35: =4000*60/250 -> 960 | Q35: =P35-H35-J35-M35-N35-O35 -> 768 | R35: =Q35-F35-G35-I35-K35-L35 -> 551 | S35: =C35*0.26 -> 430.04 | T35: =(C35-D35-E35)*0.26 -> 411.84 | U35: =R35/Q35 -> 0.71744792 | V35: =(C35-D35-E35)/C35 -> 0.95767836 | W35: =S35/R35 -> 0.78047187 | X35: =U35*V35*W35 -> 0.53625
A36: 35 | B36: P4 | C36: 1675 | D36: 24 | E36: 11 | F36: 136 | G36: 31 | H36: 15 | I36: 30 | J36: 10 | K36: 32 | L36: 36 | N36: 20 | O36: =37500/250 -> 150 | P36: =4000*60/250 -> 960 | Q36: =P36-H36-J36-M36-N36-O36 -> 765 | R36: =Q36-F36-G36-I36-K36-L36 -> 500 | S36: =C36*0.26 -> 435.5 | T36: =(C36-D36-E36)*0.26 -> 426.4 | U36: =R36/Q36 -> 0.65359477 | V36: =(C36-D36-E36)/C36 -> 0.97910448 | W36: =S36/R36 -> 0.871 | X36: =U36*V36*W36 -> 0.55738562
A37: 36 | B37: P3 | C37: 1706 | D37: 25 | E37: 21 | F37: 128 | G37: 39 | H37: 17 | I37: 35 | J37: 13 | K37: 18 | L37: 34 | N37: 18 | O37: =37500/250 -> 150 | P37: =4000*60/250 -> 960 | Q37: =P37-H37-J37-M37-N37-O37 -> 762 | R37: =Q37-F37-G37-I37-K37-L37 -> 508 | S37: =C37*0.26 -> 443.56 | T37: =(C37-D37-E37)*0.26 -> 431.6 | U37: =R37/Q37 -> 0.66666667 | V37: =(C37-D37-E37)/C37 -> 0.97303634 | W37: =S37/R37 -> 0.87314961 | X37: =U37*V37*W37 -> 0.5664042
A38: 37 | B38: P2 | C38: 1661 | D38: 13 | E38: 20 | F38: 126 | G38: 43 | H38: 20 | I38: 29 | J38: 10 | K38: 31 | L38: 27 | N38: 17 | O38: =37500/250 -> 150 | P38: =4000*60/250 -> 960 | Q38: =P38-H38-J38-M38-N38-O38 -> 763 | R38: =Q38-F38-G38-I38-K38-L38 -> 507 | S38: =C38*0.26 -> 431.86 | T38: =(C38-D38-E38)*0.26 -> 423.28 | U38: =R38/Q38 -> 0.66448231 | V38: =(C38-D38-E38)/C38 -> 0.98013245 | W38: =S38/R38 -> 0.85179487 | X38: =U38*V38*W38 -> 0.55475754
A39: 38 | B39: P1 | C39: 1747 | D39: 13 | E39: 26 | F39: 139 | G39: 31 | H39: 18 | I39: 31 | J39: 10 | K39: 22 | L39: 28 | N39: 17 | O39: =37500/250 -> 150 | P39: =4000*60/250 -> 960 | Q39: =P39-H39-J39-M39-N39-O39 -> 765 | R39: =Q39-F39-G39-I39-K39-L39 -> 514 | S39: =C39*0.26 -> 454.22 | T39: =(C39-D39-E39)*0.26 -> 444.08 | U39: =R39/Q39 -> 0.67189542 | V39: =(C39-D39-E39)/C39 -> 0.97767602 | W39: =S39/R39 -> 0.8836965 | X39: =U39*V39*W39 -> 0.58049673
A40: 39 | B40: P3 | C40: 1802 | D40: 29 | E40: 27 | F40: 140 | G40: 27 | H40: 20 | I40: 19 | J40: 6 | K40: 36 | L40: 32 | N40: 20 | O40: =37500/250 -> 150 | P40: =4000*60/250 -> 960 | Q40: =P40-H40-J40-M40-N40-O40 -> 764 | R40: =Q40-F40-G40-I40-K40-L40 -> 510 | S40: =C40*0.26 -> 468.52 | T40: =(C40-D40-E40)*0.26 -> 453.96 | U40: =R40/Q40 -> 0.66753927 | V40: =(C40-D40-E40)/C40 -> 0.96892342 | W40: =S40/R40 -> 0.91866667 | X40: =U40*V40*W40 -> 0.59418848
...

Sheet Usinage
A1: Journée | B1: Produit | C1: Quantité | D1: Rejet-Démarage | E1: Rejet qualité | F1: Panne | G1: Arrêts mineurs | H1: Nettoyage | I1: Réglage dérive machine | J1: Inspection machine | K1: changement d'outil | L1: Déplacement/Manutention | M1: Remplacement préventif | N1: Lubrification | O1: pause | P1: TO | Q1: TR | R1: tfb | S1: tn | T1: tu | U1: TD | V1: TQ | W1: TP | X1: TRS
A2: 1 | B2: P1 | C2: =Découpe!C2-Découpe!D2-Découpe!E2 -> 1809 | D2: 19 | E2: 40 | F2: 51 | G2: 8 | H2: 10 | I2: 10 | J2: 6 | K2: 32 | L2: 16 | N2: 20 | O2: =37500/250 -> 150 | P2: =4000*60/250 -> 960 | Q2: =P2-H2-J2-M2-N2-O2 -> 774 | R2: =Q2-F2-G2-I2-K2-L2 -> 657 | S2: =C2*0.2 -> 361.8 | T2: =(C2-D2-E2)*0.2 -> 350 | U2: =R2/Q2 -> 0.84883721 | V2: =(C2-D2-E2)/C2 -> 0.9673853 | W2: =S2/R2 -> 0.55068493 | X2: =U2*V2*W2 -> 0.45219638
A3: 2 | B3: P3 | C3: =Découpe!C3-Découpe!D3-Découpe!E3 -> 1709 | D3: 23 | E3: 30 | F3: 52 | G3: 11 | H3: 5 | I3: 5 | J3: 6 | K3: 13 | L3: 24 | N3: 20 | O3: =37500/250 -> 150 | P3: =4000*60/250 -> 960 | Q3: =P3-H3-J3-M3-N3-O3 -> 779 | R3: =Q3-F3-G3-I3-K3-L3 -> 674 | S3: =C3*0.2 -> 341.8 | T3: =(C3-D3-E3)*0.2 -> 331.2 | U3: =R3/Q3 -> 0.86521181 | V3: =(C3-D3-E3)/C3 -> 0.96898771 | W3: =S3/R3 -> 0.50712166 | X3: =U3*V3*W3 -> 0.42516046
A4: 3 | B4: P2 | C4: =Découpe!C4-Découpe!D4-Découpe!E4 -> 1682 | D4: 25 | E4: 19 | F4: 54 | G4: 14 | H4: 9 | I4: 9 | J4: 8 | K4: 48 | L4: 15 | N4: 16 | O4: =37500/250 -> 150 | P4: =4000*60/250 -> 960 | Q4: =P4-H4-J4-M4-N4-O4 -> 777 | R4: =Q4-F4-G4-I4-K4-L4 -> 637 | S4: =C4*0.2 -> 336.4 | T4: =(C4-D4-E4)*0.2 -> 327.6 | U4: =R4/Q4 -> 0.81981982 | V4: =(C4-D4-E4)/C4 -> 0.97384067 | W4: =S4/R4 -> 0.52810047 | X4: =U4*V4*W4 -> 0.42162162
A5: 4 | B5: P4 | C5: =Découpe!C5-Découpe!D5-Découpe!E5 -> 1767 | D5: 23 | E5: 24 | F5: 48 | G5: 6 | H5: 6 | I5: 6 | J5: 6 | K5: 31 | L5: 21 | N5: 19 | O5: =37500/250 -> 150 | P5: =4000*60/250 -> 960 | Q5: =P5-H5-J5-M5-N5-O5 -> 779 | R5: =Q5-F5-G5-I5-K5-L5 -> 667 | S5: =C5*0.2 -> 353.4 | T5: =(C5-D5-E5)*0.2 -> 344 | U5: =R5/Q5 -> 0.85622593 | V5: =(C5-D5-E5)/C5 -> 0.97340125 | W5: =S5/R5 -> 0.52983508 | X5: =U5*V5*W5 -> 0.44159178
A6: 5 | B6: P1 | C6: =Découpe!C6-Découpe!D6-Découpe!E6 -> 1670 | D6: 22 | E6: 22 | F6: 75 | G6: 5 | H6: 10 | I6: 10 | J6: 7 | K6: 44 | L6: 22 | N6: 20 | O6: =37500/250 -> 150 | P6: =4000*60/250 -> 960 | Q6: =P6-H6-J6-M6-N6-O6 -> 773 | R6: =Q6-F6-G6-I6-K6-L6 -> 617 | S6: =C6*0.2 -> 334 | T6: =(C6-D6-E6)*0.2 -> 325.2 | U6: =R6/Q6 -> 0.79818887 | V6: =(C6-D6-E6)/C6 -> 0.97365269 | W6: =S6/R6 -> 0.54132901 | X6: =U6*V6*W6 -> 0.42069858
A7: 6 | B7: P2 | C7: =Découpe!C7-Découpe!D7-Découpe!E7 -> 1816 | D7: 19 | E7: 32 | F7: 49 | G7: 7 | H7: 15 | I7: 15 | J7: 6 | K7: 48 | L7: 20 | N7: 20 | O7: =37500/250 -> 150 | P7: =4000*60/250 -> 960 | Q7: =P7-H7-J7-M7-N7-O7 -> 769 | R7: =Q7-F7-G7-I7-K7-L7 -> 630 | S7: =C7*0.2 -> 363.2 | T7: =(C7-D7-E7)*0.2 -> 353 | U7: =R7/Q7 -> 0.81924577 | V7: =(C7-D7-E7)/C7 -> 0.9719163 | W7: =S7/R7 -> 0.57650794 | X7: =U7*V7*W7 -> 0.45903771
A8: 7 | B8: P2 | C8: =Découpe!C8-Découpe!D8-Découpe!E8 -> 1819 | D8: 18 | E8: 20 | F8: 46 | G8: 11 | H8: 11 | I8: 11 | J8: 5 | L8: 23 | N8: 16 | O8: =37500/250 -> 150 | P8: =4000*60/250 -> 960 | Q8: =P8-H8-J8-M8-N8-O8 -> 778 | R8: =Q8-F8-G8-I8-K8-L8 -> 687 | S8: =C8*0.2 -> 363.8 | T8: =(C8-D8-E8)*0.2 -> 356.2 | U8: =R8/Q8 -> 0.88303342 | V8: =(C8-D8-E8)/C8 -> 0.9791094 | W8: =S8/R8 -> 0.52954876 | X8: =U8*V8*W8 -> 0.45784062
A9: 8 | B9: P4 | C9: =Découpe!C9-Découpe!D9-Découpe!E9 -> 1828 | D9: 23 | E9: 22 | F9: 48 | G9: 14 | H9: 15 | I9: 16 | J9: 8 | K9: 14 | L9: 31 | N9: 18 | O9: =37500/250 -> 150 | P9: =4000*60/250 -> 960 | Q9: =P9-H9-J9-M9-N9-O9 -> 769 | R9: =Q9-F9-G9-I9-K9-L9 -> 646 | S9: =C9*0.2 -> 365.6 | T9: =(C9-D9-E9)*0.2 -> 356.6 | U9: =R9/Q9 -> 0.84005202 | V9: =(C9-D9-E9)/C9 -> 0.97538293 | W9: =S9/R9 -> 0.56594427 | X9: =U9*V9*W9 -> 0.46371912
A10: 9 | B10: P1 | C10: =Découpe!C10-Découpe!D10-Découpe!E10 -> 1720 | D10: 22 | E10: 40 | F10: 47 | G10: 9 | H10: 8 | I10: 9 | J10: 6 | K10: 27 | L10: 31 | N10: 20 | O10: =37500/250 -> 150 | P10: =4000*60/250 -> 960 | Q10: =P10-H10-J10-M10-N10-O10 -> 776 | R10: =Q10-F10-G10-I10-K10-L10 -> 653 | S10: =C10*0.2 -> 344 | T10: =(C10-D10-E10)*0.2 -> 331.6 | U10: =R10/Q10 -> 0.84149485 | V10: =(C10-D10-E10)/C10 -> 0.96395349 | W10: =S10/R10 -> 0.52679939 | X10: =U10*V10*W10 -> 0.42731959
A11: 10 | B11: P3 | C11: =Découpe!C11-Découpe!D11-Découpe!E11 -> 1720 | D11: 16 | E11: 24 | F11: 57 | G11: 13 | H11: 11 | I11: 12 | J11: 7 | K11: 24 | L11: 14 | N11: 17 | O11: =37500/250 -> 150 | P11: =4000*60/250 -> 960 | Q11: =P11-H11-J11-M11-N11-O11 -> 775 | R11: =Q11-F11-G11-I11-K11-L11 -> 655 | S11: =C11*0.2 -> 344 | T11: =(C11-D11-E11)*0.2 -> 336 | U11: =R11/Q11 -> 0.84516129 | V11: =(C11-D11-E11)/C11 -> 0.97674419 | W11: =S11/R11 -> 0.52519084 | X11: =U11*V11*W11 -> 0.43354839
A12: 11 | B12: P2 | C12: =Découpe!C12-Découpe!D12-Découpe!E12 -> 1808 | D12: 20 | E12: 20 | F12: 68 | G12: 8 | H12: 12 | I12: 13 | J12: 6 | K12: 14 | L12: 26 | N12: 19 | O12: =37500/250 -> 150 | P12: =4000*60/250 -> 960 | Q12: =P12-H12-J12-M12-N12-O12 -> 773 | R12: =Q12-F12-G12-I12-K12-L12 -> 644 | S12: =C12*0.2 -> 361.6 | T12: =(C12-D12-E12)*0.2 -> 353.6 | U12: =R12/Q12 -> 0.83311772 | V12: =(C12-D12-E12)/C12 -> 0.97787611 | W12: =S12/R12 -> 0.56149068 | X12: =U12*V12*W12 -> 0.45743855
A13: 12 | B13: P4 | C13: =Découpe!C13-Découpe!D13-Découpe!E13 -> 1852 | D13: 29 | E13: 35 | F13: 45 | G13: 12 | H13: 15 | I13: 16 | J13: 7 | K13: 24 | L13: 22 | N13: 16 | O13: =37500/250 -> 150 | P13: =4000*60/250 -> 960 | Q13: =P13-H13-J13-M13-N13-O13 -> 772 | R13: =Q13-F13-G13-I13-K13-L13 -> 653 | S13: =C13*0.2 -> 370.4 | T13: =(C13-D13-E13)*0.2 -> 357.6 | U13: =R13/Q13 -> 0.84585492 | V13: =(C13-D13-E13)/C13 -> 0.96544276 | W13: =S13/R13 -> 0.56722818 | X13: =U13*V13*W13 -> 0.46321244
A14: 13 | B14: P2 | C14: =Découpe!C14-Découpe!D14-Découpe!E14 -> 1708 | D14: 22 | E14: 28 | F14: 73 | G14: 10 | H14: 7 | I14: 8 | J14: 8 | K14: 10 | L14: 23 | N14: 18 | O14: =37500/250 -> 150 | P14: =4000*60/250 -> 960 | Q14: =P14-H14-J14-M14-N14-O14 -> 777 | R14: =Q14-F14-G14-I14-K14-L14 -> 653 | S14: =C14*0.2 -> 341.6 | T14: =(C14-D14-E14)*0.2 -> 331.6 | U14: =R14/Q14 -> 0.84041184 | V14: =(C14-D14-E14)/C14 -> 0.970726 | W14: =S14/R14 -> 0.52312404 | X14: =U14*V14*W14 -> 0.42676963
A15: 14 | B15: P4 | C15: =Découpe!C15-Découpe!D15-Découpe!E15 -> 1785 | D15: 28 | E15: 22 | F15: 51 | G15: 10 | H15: 9 | I15: 10 | J15: 7 | K15: 16 | L15: 24 | N15: 17 | O15: =37500/250 -> 150 | P15: =4000*60/250 -> 960 | Q15: =P15-H15-J15-M15-N15-O15 -> 777 | R15: =Q15-F15-G15-I15-K15-L15 -> 666 | S15: =C15*0.2 -> 357 | T15: =(C15-D15-E15)*0.2 -> 347 | U15: =R15/Q15 -> 0.85714286 | V15: =(C15-D15-E15)/C15 -> 0.9719888 | W15: =S15/R15 -> 0.53603604 | X15: =U15*V15*W15 -> 0.44658945
A16: 15 | B16: P1 | C16: =Découpe!C16-Découpe!D16-Découpe!E16 -> 1795 | D16: 21 | E16: 21 | F16: 58 | G16: 6 | H16: 10 | I16: 11 | J16: 8 | K16: 31 | L16: 27 | N16: 15 | O16: =37500/250 -> 150 | P16: =4000*60/250 -> 960 | Q16: =P16-H16-J16-M16-N16-O16 -> 777 | R16: =Q16-F16-G16-I16-K16-L16 -> 644 | S16: =C16*0.2 -> 359 | T16: =(C16-D16-E16)*0.2 -> 350.6 | U16: =R16/Q16 -> 0.82882883 | V16: =(C16-D16-E16)/C16 -> 0.97660167 | W16: =S16/R16 -> 0.55745342 | X16: =U16*V16*W16 -> 0.45122265
A17: 16 | B17: P3 | C17: =Découpe!C17-Découpe!D17-Découpe!E17 -> 1631 | D17: 24 | E17: 40 | F17: 57 | G17: 10 | H17: 6 | I17: 7 | J17: 6 | K17: 26 | L17: 17 | N17: 19 | O17: =37500/250 -> 150 | P17: =4000*60/250 -> 960 | Q17: =P17-H17-J17-M17-N17-O17 -> 779 | R17: =Q17-F17-G17-I17-K17-L17 -> 662 | S17: =C17*0.2 -> 326.2 | T17: =(C17-D17-E17)*0.2 -> 313.4 | U17: =R17/Q17 -> 0.84980745 | V17: =(C17-D17-E17)/C17 -> 0.96076027 | W17: =S17/R17 -> 0.49274924 | X17: =U17*V17*W17 -> 0.40231065
A18: 17 | B18: P2 | C18: =Découpe!C18-Découpe!D18-Découpe!E18 -> 1677 | D18: 19 | E18: 31 | F18: 61 | G18: 15 | H18: 9 | I18: 10 | J18: 7 | K18: 30 | L18: 14 | N18: 17 | O18: =37500/250 -> 150 | P18: =4000*60/250 -> 960 | Q18: =P18-H18-J18-M18-N18-O18 -> 777 | R18: =Q18-F18-G18-I18-K18-L18 -> 647 | S18: =C18*0.2 -> 335.4 | T18: =(C18-D18-E18)*0.2 -> 325.4 | U18: =R18/Q18 -> 0.83268983 | V18: =(C18-D18-E18)/C18 -> 0.97018485 | W18: =S18/R18 -> 0.51839258 | X18: =U18*V18*W18 -> 0.41879022
A19: 18 | B19: P4 | C19: =Découpe!C19-Découpe!D19-Découpe!E19 -> 1818 | D19: 23 | E19: 40 | F19: 55 | G19: 14 | H19: 10 | I19: 12 | J19: 9 | K19: 33 | L19: 26 | N19: 20 | O19: =37500/250 -> 150 | P19: =4000*60/250 -> 960 | Q19: =P19-H19-J19-M19-N19-O19 -> 771 | R19: =Q19-F19-G19-I19-K19-L19 -> 631 | S19: =C19*0.2 -> 363.6 | T19: =(C19-D19-E19)*0.2 -> 351 | U19: =R19/Q19 -> 0.81841764 | V19: =(C19-D19-E19)/C19 -> 0.96534653 | W19: =S19/R19 -> 0.57622821 | X19: =U19*V19*W19 -> 0.45525292
A20: 19 | B20: P3 | C20: =Découpe!C20-Découpe!D20-Découpe!E20 -> 1807 | D20: 18 | E20: 22 | F20: 53 | G20: 11 | H20: 13 | I20: 14 | J20: 5 | K20: 27 | L20: 16 | N20: 17 | O20: =37500/250 -> 150 | P20: =4000*60/250 -> 960 | Q20: =P20-H20-J20-M20-N20-O20 -> 775 | R20: =Q20-F20-G20-I20-K20-L20 -> 654 | S20: =C20*0.2 -> 361.4 | T20: =(C20-D20-E20)*0.2 -> 353.4 | U20: =R20/Q20 -> 0.84387097 | V20: =(C20-D20-E20)/C20 -> 0.97786386 | W20: =S20/R20 -> 0.55259939 | X20: =U20*V20*W20 -> 0.456
... A27: 26 | B27: P2 | C27: =Découpe!C27-Découpe!D27-Découpe!E27 -> 1741 | D27: 22 | E27: 29 | F27: 64 | G27: 8 | H27: 13 | I27: 16 | J27: 5 | K27: 13 | L27: 32 | N27: 17 | O27: =37500/250 -> 150 | P27: =4000*60/250 -> 960 | Q27: =P27-H27-J27-M27-N27-O27 -> 775 | R27: =Q27-F27-G27-I27-K27-L27 -> 642 | S27: =C27*0.2 -> 348.2 | T27: =(C27-D27-E27)*0.2 -> 338 | U27: =R27/Q27 -> 0.8283871 | V27: =(C27-D27-E27)/C27 -> 0.97070649 | W27: =S27/R27 -> 0.5423676 | X27: =U27*V27*W27 -> 0.43612903
A28: 27 | B28: P4 | C28: =Découpe!C28-Découpe!D28-Découpe!E28 -> 1628 | D28: 25 | E28: 23 | F28: 74 | G28: 14 | H28: 11 | I28: 14 | J28: 8 | K28: 18 | L28: 22 | M28: 60 | N28: 15 | O28: =37500/250 -> 150 | P28: =4000*60/250 -> 960 | Q28: =P28-H28-J28-M28-N28-O28 -> 716 | R28: =Q28-F28-G28-I28-K28-L28 -> 574 | S28: =C28*0.2 -> 325.6 | T28: =(C28-D28-E28)*0.2 -> 316 | U28: =R28/Q28 -> 0.80167598 | V28: =(C28-D28-E28)/C28 -> 0.97051597 | W28: =S28/R28 -> 0.56724739 | X28: =U28*V28*W28 -> 0.44134078
A29: 28 | B29: P4 | C29: =Découpe!C29-Découpe!D29-Découpe!E29 -> 1666 | D29: 18 | E29: 37 | F29: 47 | G29: 9 | H29: 15 | I29: 19 | J29: 6 | L29: 20 | N29: 18 | O29: =37500/250 -> 150 | P29: =4000*60/250 -> 960 | Q29: =P29-H29-J29-M29-N29-O29 -> 771 | R29: =Q29-F29-G29-I29-K29-L29 -> 676 | S29: =C29*0.2 -> 333.2 | T29: =(C29-D29-E29)*0.2 -> 322.2 | U29: =R29/Q29 -> 0.8767834 | V29: =(C29-D29-E29)/C29 -> 0.96698679 | W29: =S29/R29 -> 0.49289941 | X29: =U29*V29*W29 -> 0.41789883
A30: 29 | B30: P3 | C30: =Découpe!C30-Découpe!D30-Découpe!E30 -> 1787 | D30: 28 | E30: 36 | F30: 61 | G30: 19 | H30: 9 | I30: 10 | J30: 8 | K30: 18 | L30: 28 | N30: 15 | O30: =37500/250 -> 150 | P30: =4000*60/250 -> 960 | Q30: =P30-H30-J30-M30-N30-O30 -> 778 | R30: =Q30-F30-G30-I30-K30-L30 -> 642 | S30: =C30*0.2 -> 357.4 | T30: =(C30-D30-E30)*0.2 -> 344.6 | U30: =R30/Q30 -> 0.8251928 | V30: =(C30-D30-E30)/C30 -> 0.96418579 | W30: =S30/R30 -> 0.55669782 | X30: =U30*V30*W30 -> 0.44293059
A31: 30 | B31: P2 | C31: =Découpe!C31-Découpe!D31-Découpe!E31 -> 1787 | D31: 24 | E31: 21 | F31: 70 | G31: 10 | H31: 11 | I31: 15 | J31: 8 | K31: 33 | L31: 18 | N31: 15 | O31: =37500/250 -> 150 | P31: =4000*60/250 -> 960 | Q31: =P31-H31-J31-M31-N31-O31 -> 776 | R31: =Q31-F31-G31-I31-K31-L31 -> 630 | S31: =C31*0.2 -> 357.4 | T31: =(C31-D31-E31)*0.2 -> 348.4 | U31: =R31/Q31 -> 0.81185567 | V31: =(C31-D31-E31)/C31 -> 0.97481813 | W31: =S31/R31 -> 0.56730159 | X31: =U31*V31*W31 -> 0.44896907
A32: 31 | B32: P1 | C32: =Découpe!C32-Découpe!D32-Découpe!E32 -> 1743 | D32: 20 | E32: 23 | F32: 56 | G32: 16 | H32: 14 | I32: 15 | J32: 8 | K32: 37 | L32: 26 | N32: 15 | O32: =37500/250 -> 150 | P32: =4000*60/250 -> 960 | Q32: =P32-H32-J32-M32-N32-O32 -> 773 | R32: =Q32-F32-G32-I32-K32-L32 -> 623 | S32: =C32*0.2 -> 348.6 | T32: =(C32-D32-E32)*0.2 -> 340 | U32: =R32/Q32 -> 0.80595084 | V32: =(C32-D32-E32)/C32 -> 0.97532989 | W32: =S32/R32 -> 0.55955056 | X32: =U32*V32*W32 -> 0.43984476
A33: 32 | B33: P3 | C33: =Découpe!C33-Découpe!D33-Découpe!E33 -> 1671 | D33: 21 | E33: 34 | F33: 65 | G33: 19 | H33: 8 | I33: 11 | J33: 5 | K33: 33 | L33: 25 | N33: 16 | O33: =37500/250 -> 150 | P33: =4000*60/250 -> 960 | Q33: =P33-H33-J33-M33-N33-O33 -> 781 | R33: =Q33-F33-G33-I33-K33-L33 -> 628 | S33: =C33*0.2 -> 334.2 | T33: =(C33-D33-E33)*0.2 -> 323.2 | U33: =R33/Q33 -> 0.80409731 | V33: =(C33-D33-E33)/C33 -> 0.96708558 | W33: =S33/R33 -> 0.53216561 | X33: =U33*V33*W33 -> 0.41382843
A34: 33 | B34: P2 | C34: =Découpe!C34-Découpe!D34-Découpe!E34 -> 1674 | D34: 19 | E34: 31 | F34: 61 | G34: 14 | H34: 11 | I34: 14 | J34: 7 | K34: 45 | L34: 33 | N34: 16 | O34: =37500/250 -> 150 | P34: =4000*60/250 -> 960 | Q34: =P34-H34-J34-M34-N34-O34 -> 776 | R34: =Q34-F34-G34-I34-K34-L34 -> 609 | S34: =C34*0.2 -> 334.8 | T34: =(C34-D34-E34)*0.2 -> 324.8 | U34: =R34/Q34 -> 0.78479381 | V34: =(C34-D34-E34)/C34 -> 0.97013142 | W34: =S34/R34 -> 0.54975369 | X34: =U34*V34*W34 -> 0.4185567
A35: 34 | B35: P2 | C35: =Découpe!C35-Découpe!D35-Découpe!E35 -> 1584 | D35: 20 | E35: 25 | F35: 65 | G35: 9 | H35: 13 | I35: 19 | J35: 7 | L35: 17 | N35: 17 | O35: =37500/250 -> 150 | P35: =4000*60/250 -> 960 | Q35: =P35-H35-J35-M35-N35-O35 -> 773 | R35: =Q35-F35-G35-I35-K35-L35 -> 663 | S35: =C35*0.2 -> 316.8 | T35: =(C35-D35-E35)*0.2 -> 307.8 | U35: =R35/Q35 -> 0.85769728 | V35: =(C35-D35-E35)/C35 -> 0.97159091 | W35: =S35/R35 -> 0.47782805 | X35: =U35*V35*W35 -> 0.39818887
A36: 35 | B36: P4 | C36: =Découpe!C36-Découpe!D36-Découpe!E36 -> 1640 | D36: 17 | E36: 32 | F36: 61 | G36: 7 | H36: 11 | I36: 14 | J36: 5 | K36: 46 | L36: 22 | N36: 16 | O36: =37500/250 -> 150 | P36: =4000*60/250 -> 960 | Q36: =P36-H36-J36-M36-N36-O36 -> 778 | R36: =Q36-F36-G36-I36-K36-L36 -> 628 | S36: =C36*0.2 -> 328 | T36: =(C36-D36-E36)*0.2 -> 318.2 | U36: =R36/Q36 -> 0.80719794 | V36: =(C36-D36-E36)/C36 -> 0.97012195 | W36: =S36/R36 -> 0.52229299 | X36: =U36*V36*W36 -> 0.40899743
A37: 36 | B37: P3 | C37: =Découpe!C37-Découpe!D37-Découpe!E37 -> 1660 | D37: 17 | E37: 30 | F37: 46 | G37: 14 | H37: 6 | I37: 7 | J37: 8 | K37: 11 | L37: 27 | N37: 20 | O37: =37500/250 -> 150 | P37: =4000*60/250 -> 960 | Q37: =P37-H37-J37-M37-N37-O37 -> 776 | R37: =Q37-F37-G37-I37-K37-L37 -> 671 | S37: =C37*0.2 -> 332 | T37: =(C37-D37-E37)*0.2 -> 322.6 | U37: =R37/Q37 -> 0.86469072 | V37: =(C37-D37-E37)/C37 -> 0.97168675 | W37: =S37/R37 -> 0.4947839 | X37: =U37*V37*W37 -> 0.41572165
A38: 37 | B38: P2 | C38: =Découpe!C38-Découpe!D38-Découpe!E38 -> 1628 | D38: 18 | E38: 30 | F38: 54 | G38: 11 | H38: 8 | I38: 12 | J38: 7 | K38: 31 | L38: 15 | N38: 17 | O38: =37500/250 -> 150 | P38: =4000*60/250 -> 960 | Q38: =P38-H38-J38-M38-N38-O38 -> 778 | R38: =Q38-F38-G38-I38-K38-L38 -> 655 | S38: =C38*0.2 -> 325.6 | T38: =(C38-D38-E38)*0.2 -> 316 | U38: =R38/Q38 -> 0.84190231 | V38: =(C38-D38-E38)/C38 -> 0.97051597 | W38: =S38/R38 -> 0.49709924 | X38: =U38*V38*W38 -> 0.40616967
A39: 38 | B39: P1 | C39: =Découpe!C39-Découpe!D39-Découpe!E39 -> 1708 | D39: 21 | E39: 27 | F39: 57 | G39: 7 | H39: 10 | I39: 12 | J39: 9 | K39: 22 | L39: 22 | N39: 15 | O39: =37500/250 -> 150 | P39: =4000*60/250 -> 960 | Q39: =P39-H39-J39-M39-N39-O39 -> 776 | R39: =Q39-F39-G39-I39-K39-L39 -> 656 | S39: =C39*0.2 -> 341.6 | T39: =(C39-D39-E39)*0.2 -> 332 | U39: =R39/Q39 -> 0.84536082 | V39: =(C39-D39-E39)/C39 -> 0.97189696 | W39: =S39/R39 -> 0.52073171 | X39: =U39*V39*W39 -> 0.42783505
A40: 39 | B40: P3 | C40: =Découpe!C40-Découpe!D40-Découpe!E40 -> 1746 | D40: 19 | E40: 35 | F40: 69 | G40: 15 | H40: 6 | I40: 10 | J40: 8 | K40: 33 | L40: 24 | N40: 16 | O40: =37500/250 -> 150 | P40: =4000*60/250 -> 960 | Q40: =P40-H40-J40-M40-N40-O40 -> 780 | R40: =Q40-F40-G40-I40-K40-L40 -> 629 | S40: =C40*0.2 -> 349.2 | T40: =(C40-D40-E40)*0.2 -> 338.4 | U40: =R40/Q40 -> 0.80641026 | V40: =(C40-D40-E40)/C40 -> 0.96907216 | W40: =S40/R40 -> 0.55516693 | X40: =U40*V40*W40 -> 0.43384615
A41: 40 | B41: P2 | C41: =Découpe!C41-Découpe!D41-Découpe!E41 -> 1719 | D41: 23 | E41: 35 | F41: 58 | G41: 14 | H41: 9 | I41: 16 | J41: 9 | K41: 45 | L41: 22 | N41: 17 | O41: =37500/250 -> 150 | P41: =4000*60/250 -> 960 | Q41: =P41-H41-J41-M41-N41-O41 -> 775 | R41: =Q41-F41-G41-I41-K41-L41 -> 620 | S41: =C41*0.2 -> 343.8 | T41: =(C41-D41-E41)*0.2 -> 332.2 | U41: =R41/Q41 -> 0.8 | V41: =(C41-D41-E41)/C41 -> 0.96625945 | W41: =S41/R41 -> 0.55451613 | X41: =U41*V41*W41 -> 0.42864516
A42: 41 | B42: P4 | C42: =Découpe!C42-Découpe!D42-Découpe!E42 -> 1631 | D42: 22 | E42: 19 | F42: 61 | G42: 12 | H42: 7 | I42: 10 | J42: 5 | K42: 46 | L42: 23 | N42: 16 | O42: =37500/250 -> 150 | P42: =4000*60/250 -> 960 | Q42: =P42-H42-J42-M42-N42-O42 -> 782 | R42: =Q42-F42-G42-I42-K42-L42 -> 630 | S42: =C42*0.2 -> 326.2 | T42: =(C42-D42-E42)*0.2 -> 318 | U42: =R42/Q42 -> 0.8056266 | V42: =(C42-D42-E42)/C42 -> 0.97486205 | W42: =S42/R42 -> 0.51777778 | X42: =U42*V42*W42 -> 0.40664962
A43: 42 | B43: P3 | C43: =Découpe!C43-Découpe!D43-Découpe!E43 -> 1539 | D43: 21 | E43: 35 | F43: 55 | G43: 6 | H43: 8 | I43: 12 | J43: 5 | K43: 44 | L43: 21 | N43: 20 | O43: =37500/250 -> 150 | P43: =4000*60/250 -> 960 | Q43: =P43-H43-J43-M43-N43-O43 -> 777 | R43: =Q43-F43-G43-I43-K43-L43 -> 639 | S43: =C43*0.2 -> 307.8 | T43: =(C43-D43-E43)*0.2 -> 296.6 | U43: =R43/Q43 -> 0.82239382 | V43: =(C43-D43-E43)/C43 -> 0.96361274 | W43: =S43/R43 -> 0.48169014 | X43: =U43*V43*W43 -> 0.38172458
A44: 43 | B44: P2 | C44: =Découpe!C44-Découpe!D44-Découpe!E44 -> 1698 | D44: 23 | E44: 28 | F44: 72 | G44: 17 | H44: 8 | I44: 14 | J44: 7 | K44: 43 | L44: 28 | N44: 19 | O44: =37500/250 -> 150 | P44: =4000*60/250 -> 960 | Q44: =P44-H44-J44-M44-N44-O44 -> 776 | R44: =Q44-F44-G44-I44-K44-L44 -> 602 | S44: =C44*0.2 -> 339.6 | T44: =(C44-D44-E44)*0.2 -> 329.4 | U44: =R44/Q44 -> 0.7757732 | V44: =(C44-D44-E44)/C44 -> 0.96996466 | W44: =S44/R44 -> 0.5641196 | X44: =U44*V44*W44 -> 0.42448454
A45: 44 | B45: P1 | C45: =Découpe!C45-Découpe!D45-Découpe!E45 -> 1680 | D45: 21 | E45: 28 | F45: 66 | G45: 13 | H45: 13 | I45: 16 | J45: 8 | K45: 33 | L45: 28 | N45: 18 | O45: =37500/250 -> 150 | P45: =4000*60/250 -> 960 | Q45: =P45-H45-J45-M45-N45-O45 -> 771 | R45: =Q45-F45-G45-I45-K45-L45 -> 615 | S45: =C45*0.2 -> 336 | T45: =(C45-D45-E45)*0.2 -> 326.2 | U45: =R45/Q45 -> 0.79766537 | V45: =(C45-D45-E45)/C45 -> 0.97083333 | W45: =S45/R45 -> 0.54634146 | X45: =U45*V45*W45 -> 0.4230869
A46: 45 | B46: P3 | C46: =Découpe!C46-Découpe!D46-Découpe!E46 -> 1511 | D46: 17 | E46: 37 | F46: 58 | G46: 10 | H46: 14 | I46: 20 | J46: 8 | K46: 21 | L46: 22 | N46: 15 | O46: =37500/250 -> 150 | P46: =4000*60/250 -> 960 | Q46: =P46-H46-J46-M46-N46-O46 -> 773 | R46: =Q46-F46-G46-I46-K46-L46 -> 642 | S46: =C46*0.2 -> 302.2 | T46: =(C46-D46-E46)*0.2 -> 291.4 | U46: =R46/Q46 -> 0.8305304 | V46: =(C46-D46-E46)/C46 -> 0.96426208 | W46: =S46/R46 -> 0.47071651 | X46: =U46*V46*W46 -> 0.37697283
...

Sheet Peinture
A1: Journée | B1: Produit | C1: Quantité | D1: Rejet-Démarage | E1: Rejet qualité | F1: Panne | G1: Arrêts mineurs | H1: Nettoyage | I1: Réglage dérive machine | J1: Inspection machine | K1: changement d'outil | L1: Déplacement/Manutention | M1: Remplacement préventif | N1: Lubrification | O1: pause | P1: TO | Q1: TR | R1: tfb | S1: tn | T1: tu | U1: TD | V1: TQ | W1: TP | X1: TRS
A2: 1 | B2: P1 | C2: =Usinage!C2-Usinage!D2-Usinage!E2 -> 1750 | D2: 59 | E2: 150 | F2: 36 | G2: 24 | H2: 5 | I2: 18 | J2: 21 | L2: 115 | N2: 6 | O2: =37500/250 -> 150 | P2: =4000*60/250 -> 960 | Q2: =P2-H2-J2-M2-N2-O2 -> 778 | R2: =Q2-F2-G2-I2-K2-L2 -> 585 | S2: =C2*0.264 -> 462 | T2: =(C2-D2-E2)*0.264 -> 406.824 | U2: =R2/Q2 -> 0.75192802 | V2: =(C2-D2-E2)/C2 -> 0.88057143 | W2: =S2/R2 -> 0.78974359 | X2: =U2*V2*W2 -> 0.52291003
A3: 2 | B3: P3 | C3: =Usinage!C3-Usinage!D3-Usinage!E3 -> 1656 | D3: 56 | E3: 144 | F3: 45 | G3: 18 | H3: 10 | I3: 16 | J3: 23 | L3: 136 | N3: 9 | O3: =37500/250 -> 150 | P3: =4000*60/250 -> 960 | Q3: =P3-H3-J3-M3-N3-O3 -> 768 | R3: =Q3-F3-G3-I3-K3-L3 -> 553 | S3: =C3*0.264 -> 437.184 | T3: =(C3-D3-E3)*0.264 -> 384.384 | U3: =R3/Q3 -> 0.72005208 | V3: =(C3-D3-E3)/C3 -> 0.87922705 | W3: =S3/R3 -> 0.79056781 | X3: =U3*V3*W3 -> 0.5005
A4: 3 | B4: P2 | C4: =Usinage!C4-Usinage!D4-Usinage!E4 -> 1638 | D4: 59 | E4: 156 | G4: 41 | H4: 5 | I4: 15 | J4: 23 | L4: 126 | N4: 9 | O4: =37500/250 -> 150 | P4: =4000*60/250 -> 960 | Q4: =P4-H4-J4-M4-N4-O4 -> 773 | R4: =Q4-F4-G4-I4-K4-L4 -> 591 | S4: =C4*0.264 -> 432.432 | T4: =(C4-D4-E4)*0.264 -> 375.672 | U4: =R4/Q4 -> 0.76455369 | V4: =(C4-D4-E4)/C4 -> 0.86874237 | W4: =S4/R4 -> 0.73169543 | X4: =U4*V4*W4 -> 0.48599224
A5: 4 | B5: P4 | C5: =Usinage!C5-Usinage!D5-Usinage!E5 -> 1720 | D5: 47 | E5: 182 | G5: 38 | H5: 5 | I5: 18 | J5: 20 | L5: 106 | O5: =37500/250 -> 150 | P5: =4000*60/250 -> 960 | Q5: =P5-H5-J5-M5-N5-O5 -> 785 | R5: =Q5-F5-G5-I5-K5-L5 -> 623 | S5: =C5*0.264 -> 454.08 | T5: =(C5-D5-E5)*0.264 -> 393.624 | U5: =R5/Q5 -> 0.79363057 | V5: =(C5-D5-E5)/C5 -> 0.86686047 | W5: =S5/R5 -> 0.72886035 | X5: =U5*V5*W5 -> 0.50143185
A6: 5 | B6: P1 | C6: =Usinage!C6-Usinage!D6-Usinage!E6 -> 1626 | D6: 43 | E6: 185 | G6: 33 | H6: 6 | I6: 19 | J6: 24 | L6: 111 | O6: =37500/250 -> 150 | P6: =4000*60/250 -> 960 | Q6: =P6-H6-J6-M6-N6-O6 -> 780 | R6: =Q6-F6-G6-I6-K6-L6 -> 617 | S6: =C6*0.264 -> 429.264 | T6: =(C6-D6-E6)*0.264 -> 369.072 | U6: =R6/Q6 -> 0.79102564 | V6: =(C6-D6-E6)/C6 -> 0.8597786 | W6: =S6/R6 -> 0.69572771 | X6: =U6*V6*W6 -> 0.47316923
A7: 6 | B7: P2 | C7: =Usinage!C7-Usinage!D7-Usinage!E7 -> 1765 | D7: 52 | E7: 198 | G7: 36 | H7: 6 | I7: 22 | J7: 24 | L7: 122 | O7: =37500/250 -> 150 | P7: =4000*60/250 -> 960 | Q7: =P7-H7-J7-M7-N7-O7 -> 780 | R7: =Q7-F7-G7-I7-K7-L7 -> 600 | S7: =C7*0.264 -> 465.96 | T7: =(C7-D7-E7)*0.264 -> 399.96 | U7: =R7/Q7 -> 0.76923077 | V7: =(C7-D7-E7)/C7 -> 0.85835694 | W7: =S7/R7 -> 0.7766 | X7: =U7*V7*W7 -> 0.51276923
A8: 7 | B8: P2 | C8: =Usinage!C8-Usinage!D8-Usinage!E8 -> 1781 | D8: 56 | E8: 161 | G8: 44 | H8: 8 | I8: 16 | J8: 25 | L8: 125 | O8: =37500/250 -> 150 | P8: =4000*60/250 -> 960 | Q8: =P8-H8-J8-M8-N8-O8 -> 777 | R8: =Q8-F8-G8-I8-K8-L8 -> 592 | S8: =C8*0.264 -> 470.184 | T8: =(C8-D8-E8)*0.264 -> 412.896 | U8: =R8/Q8 -> 0.76190476 | V8: =(C8-D8-E8)/C8 -> 0.87815834 | W8: =S8/R8 -> 0.79422973 | X8: =U8*V8*W8 -> 0.53139768
A9: 8 | B9: P4 | C9: =Usinage!C9-Usinage!D9-Usinage!E9 -> 1783 | D9: 53 | E9: 161 | G9: 31 | H9: 8 | I9: 25 | J9: 22 | L9: 112 | O9: =37500/250 -> 150 | P9: =4000*60/250 -> 960 | Q9: =P9-H9-J9-M9-N9-O9 -> 780 | R9: =Q9-F9-G9-I9-K9-L9 -> 612 | S9: =C9*0.264 -> 470.712 | T9: =(C9-D9-E9)*0.264 -> 414.216 | U9: =R9/Q9 -> 0.78461538 | V9: =(C9-D9-E9)/C9 -> 0.87997757 | W9: =S9/R9 -> 0.76913725 | X9: =U9*V9*W9 -> 0.53104615
A10: 9 | B10: P1 | C10: =Usinage!C10-Usinage!D10-Usinage!E10 -> 1658 | D10: 44 | E10: 175 | G10: 32 | H10: 7 | I10: 22 | J10: 22 | L10: 126 | O10: =37500/250 -> 150 | P10: =4000*60/250 -> 960 | Q10: =P10-H10-J10-M10-N10-O10 -> 781 | R10: =Q10-F10-G10-I10-K10-L10 -> 601 | S10: =C10*0.264 -> 437.712 | T10: =(C10-D10-E10)*0.264 -> 379.896 | U10: =R10/Q10 -> 0.76952625 | V10: =(C10-D10-E10)/C10 -> 0.86791315 | W10: =S10/R10 -> 0.72830616 | X10: =U10*V10*W10 -> 0.48642254
A11: 10 | B11: P3 | C11: =Usinage!C11-Usinage!D11-Usinage!E11 -> 1680 | D11: 54 | E11: 151 | G11: 47 | H11: 9 | I11: 25 | J11: 24 | L11: 123 | O11: =37500/250 -> 150 | P11: =4000*60/250 -> 960 | Q11: =P11-H11-J11-M11-N11-O11 -> 777 | R11: =Q11-F11-G11-I11-K11-L11 -> 582 | S11: =C11*0.264 -> 443.52 | T11: =(C11-D11-E11)*0.264 -> 389.4 | U11: =R11/Q11 -> 0.74903475 | V11: =(C11-D11-E11)/C11 -> 0.87797619 | W11: =S11/R11 -> 0.76206186 | X11: =U11*V11*W11 -> 0.5011583
A12: 11 | B12: P2 | C12: =Usinage!C12-Usinage!D12-Usinage!E12 -> 1768 | D12: 51 | E12: 179 | G12: 47 | H12: 5 | I12: 23 | J12: 22 | L12: 120 | N12: 7 | O12: =37500/250 -> 150 | P12: =4000*60/250 -> 960 | Q12: =P12-H12-J12-M12-N12-O12 -> 776 | R12: =Q12-F12-G12-I12-K12-L12 -> 586 | S12: =C12*0.264 -> 466.752 | T12: =(C12-D12-E12)*0.264 -> 406.032 | U12: =R12/Q12 -> 0.75515464 | V12: =(C12-D12-E12)/C12 -> 0.8699095 | W12: =S12/R12 -> 0.79650512 | X12: =U12*V12*W12 -> 0.52323711
A13: 12 | B13: P4 | C13: =Usinage!C13-Usinage!D13-Usinage!E13 -> 1788 | D13: 43 | E13: 127 | G13: 40 | H13: 5 | I13: 26 | J13: 20 | L13: 135 | N13: 5 | O13: =37500/250 -> 150 | P13: =4000*60/250 -> 960 | Q13: =P13-H13-J13-M13-N13-O13 -> 780 | R13: =Q13-F13-G13-I13-K13-L13 -> 579 | S13: =C13*0.264 -> 472.032 | T13: =(C13-D13-E13)*0.264 -> 427.152 | U13: =R13/Q13 -> 0.74230769 | V13: =(C13-D13-E13)/C13 -> 0.9049217 | W13: =S13/R13 -> 0.81525389 | X13: =U13*V13*W13 -> 0.54763077
A14: 13 | B14: P2 | C14: =Usinage!C14-Usinage!D14-Usinage!E14 -> 1658 | D14: 59 | E14: 179 | G14: 39 | H14: 7 | I14: 22 | J14: 24 | L14: 138 | N14: 7 | O14: =37500/250 -> 150 | P14: =4000*60/250 -> 960 | Q14: =P14-H14-J14-M14-N14-O14 -> 772 | R14: =Q14-F14-G14-I14-K14-L14 -> 573 | S14: =C14*0.264 -> 437.712 | T14: =(C14-D14-E14)*0.264 -> 374.88 | U14: =R14/Q14 -> 0.74222798 | V14: =(C14-D14-E14)/C14 -> 0.85645356 | W14: =S14/R14 -> 0.76389529 | X14: =U14*V14*W14 -> 0.48559585
A15: 14 | B15: P4 | C15: =Usinage!C15-Usinage!D15-Usinage!E15 -> 1735 | D15: 46 | E15: 149 | G15: 28 | H15: 10 | I15: 22 | J15: 22 | L15: 140 | O15: =37500/250 -> 150 | P15: =4000*60/250 -> 960 | Q15: =P15-H15-J15-M15-N15-O15 -> 778 | R15: =Q15-F15-G15-I15-K15-L15 -> 588 | S15: =C15*0.264 -> 458.04 | T15: =(C15-D15-E15)*0.264 -> 406.56 | U15: =R15/Q15 -> 0.75578406 | V15: =(C15-D15-E15)/C15 -> 0.88760807 | W15: =S15/R15 -> 0.77897959 | X15: =U15*V15*W15 -> 0.52257069
A16: 15 | B16: P1 | C16: =Usinage!C16-Usinage!D16-Usinage!E16 -> 1753 | D16: 60 | E16: 177 | G16: 41 | H16: 8 | I16: 28 | J16: 23 | L16: 137 | O16: =37500/250 -> 150 | P16: =4000*60/250 -> 960 | Q16: =P16-H16-J16-M16-N16-O16 -> 779 | R16: =Q16-F16-G16-I16-K16-L16 -> 573 | S16: =C16*0.264 -> 462.792 | T16: =(C16-D16-E16)*0.264 -> 400.224 | U16: =R16/Q16 -> 0.73555841 | V16: =(C16-D16-E16)/C16 -> 0.86480319 | W16: =S16/R16 -> 0.80766492 | X16: =U16*V16*W16 -> 0.51376637
A17: 16 | B17: P3 | C17: =Usinage!C17-Usinage!D17-Usinage!E17 -> 1567 | D17: 48 | E17: 146 | F17: 43 | G17: 27 | H17: 10 | I17: 22 | J17: 25 | L17: 123 | N17: 8 | O17: =37500/250 -> 150 | P17: =4000*60/250 -> 960 | Q17: =P17-H17-J17-M17-N17-O17 -> 767 | R17: =Q17-F17-G17-I17-K17-L17 -> 552 | S17: =C17*0.264 -> 413.688 | T17: =(C17-D17-E17)*0.264 -> 362.472 | U17: =R17/Q17 -> 0.71968709 | V17: =(C17-D17-E17)/C17 -> 0.87619655 | W17: =S17/R17 -> 0.74943478 | X17: =U17*V17*W17 -> 0.47258409
A18: 17 | B18: P2 | C18: =Usinage!C18-Usinage!D18-Usinage!E18 -> 1627 | D18: 45 | E18: 143 | G18: 24 | H18: 6 | I18: 27 | J18: 23 | L18: 133 | N18: 8 | O18: =37500/250 -> 150 | P18: =4000*60/250 -> 960 | Q18: =P18-H18-J18-M18-N18-O18 -> 773 | R18: =Q18-F18-G18-I18-K18-L18 -> 589 | S18: =C18*0.264 -> 429.528 | T18: =(C18-D18-E18)*0.264 -> 379.896 | U18: =R18/Q18 -> 0.76196636 | V18: =(C18-D18-E18)/C18 -> 0.88444991 | W18: =S18/R18 -> 0.72924958 | X18: =U18*V18*W18 -> 0.49145666
A19: 18 | B19: P4 | C19: =Usinage!C19-Usinage!D19-Usinage!E19 -> 1755 | D19: 50 | E19: 170 | G19: 29 | H19: 5 | I19: 24 | J19: 25 | L19: 117 | O19: =37500/250 -> 150 | P19: =4000*60/250 -> 960 | Q19: =P19-H19-J19-M19-N19-O19 -> 780 | R19: =Q19-F19-G19-I19-K19-L19 -> 610 | S19: =C19*0.264 -> 463.32 | T19: =(C19-D19-E19)*0.264 -> 405.24 | U19: =R19/Q19 -> 0.78205128 | V19: =(C19-D19-E19)/C19 -> 0.87464387 | W19: =S19/R19 -> 0.75954098 | X19: =U19*V19*W19 -> 0.51953846
A20: 19 | B20: P3 | C20: =Usinage!C20-Usinage!D20-Usinage!E20 -> 1767 | D20: 44 | E20: 186 | G20: 36 | H20: 7 | I20: 25 | J20: 24 | L20: 120 | N20: 5 | O20: =37500/250 -> 150 | P20: =4000*60/250 -> 960 | Q20: =P20-H20-J20-M20-N20-O20 -> 774 | R20: =Q20-F20-G20-I20-K20-L20 -> 593 | S20: =C20*0.264 -> 466.488 | T20: =(C20-D20-E20)*0.264 -> 405.768 | U20: =R20/Q20 -> 0.76614987 | V20: =(C20-D20-E20)/C20 -> 0.86983588 | W20: =S20/R20 -> 0.78665767 | X20: =U20*V20*W20 -> 0.52424806
A21: 20 | B21: P2 | C21: =Usinage!C21-Usinage!D21-Usinage!E21 -> 1704 | D21: 59 | E21: 132 | G21: 39 | H21: 7 | I21: 21 | J21: 20 | L21: 91 | N21: 7 | O21: =37500/250 -> 150 | P21: =4000*60/250 -> 960 | Q21: =P21-H21-J21-M21-N21-O21 -> 776 | R21: =Q21-F21-G21-I21-K21-L21 -> 625 | S21: =C21*0.264 -> 449.856 | T21: =(C21-D21-E21)*0.264 -> 399.432 | U21: =R21/Q21 -> 0.80541237 | V21: =(C21-D21-E21)/C21 -> 0.8879108 | W21: =S21/R21 -> 0.7197696 | X21: =U21*V21*W21 -> 0.51473196
A22: 21 | B22: P1 | C22: =Usinage!C22-Usinage!D22-Usinage!E22 -> 1791 | D22: 42 | E22: 175 | G22: 33 | H22: 7 | I22: 25 | J22: 25 | L22: 119 | O22: =37500/250 -> 150 | P22: =4000*60/250 -> 960 | Q22: =P22-H22-J22-M22-N22-O22 -> 778 | R22: =Q22-F22-G22-I22-K22-L22 -> 601 | S22: =C22*0.264 -> 472.824 | T22: =(C22-D22-E22)*0.264 -> 415.536 | U22: =R22/Q22 -> 0.77249357 | V22: =(C22-D22-E22)/C22 -> 0.87883864 | W22: =S22/R22 -> 0.78672879 | X22: =U22*V22*W22 -> 0.53410797
A23: 22 | B23: P3 | C23: =Usinage!C23-Usinage!D23-Usinage!E23 -> 1790 | D23: 44 | E23: 169 | F23: 50 | G23: 48 | H23: 7 | I23: 21 | J23: 22 | L23: 124 | O23: =37500/250 -> 150 | P23: =4000*60/250 -> 960 | Q23: =P23-H23-J23-M23-N23-O23 -> 781 | R23: =Q23-F23-G23-I23-K23-L23 -> 538 | S23: =C23*0.264 -> 472.56 | T23: =(C23-D23-E23)*0.264 -> 416.328 | U23: =R23/Q23 -> 0.68886044 | V23: =(C23-D23-E23)/C23 -> 0.88100559 | W23: =S23/R23 -> 0.87836431 | X23: =U23*V23*W23 -> 0.53307042
A24: 23 | B24: P2 | C24: =Usinage!C24-Usinage!D24-Usinage!E24 -> 1699 | D24: 58 | E24: 168 | F24: 45 | G24: 47 | H24: 7 | I24: 27 | J24: 22 | L24: 101 | O24: =37500/250 -> 150 | P24: =4000*60/250 -> 960 | Q24: =P24-H24-J24-M24-N24-O24 -> 781 | R24: =Q24-F24-G24-I24-K24-L24 -> 561 | S24: =C24*0.264 -> 448.536 | T24: =(C24-D24-E24)*0.264 -> 388.872 | U24: =R24/Q24 -> 0.71830986 | V24: =(C24-D24-E24)/C24 -> 0.86698058 | W24: =S24/R24 -> 0.79952941 | X24: =U24*V24*W24 -> 0.49791549
A25: 24 | B25: P4 | C25: =Usinage!C25-Usinage!D25-Usinage!E25 -> 1646 | D25: 58 | E25: 174 | F25: 41 | G25: 42 | H25: 9 | I25: 19 | J25: 22 | L25: 128 | O25: =37500/250 -> 150 | P25: =4000*60/250 -> 960 | Q25: =P25-H25-J25-M25-N25-O25 -> 779 | R25: =Q25-F25-G25-I25-K25-L25 -> 549 | S25: =C25*0.264 -> 434.544 | T25: =(C25-D25-E25)*0.264 -> 373.296 | U25: =R25/Q25 -> 0.70474968 | V25: =(C25-D25-E25)/C25 -> 0.85905225 | W25: =S25/R25 -> 0.79151913 | X25: =U25*V25*W25 -> 0.47919897
A26: 25 | B26: P3 | C26: =Usinage!C26-Usinage!D26-Usinage!E26 -> 1748 | D26: 48 | E26: 183 | G26: 17 | H26: 10 | I26: 30 | J26: 21 | L26: 104 | O26: =37500/250 -> 150 | P26: =4000*60/250 -> 960 | Q26: =P26-H26-J26-M26-N26-O26 -> 779 | R26: =Q26-F26-G26-I26-K26-L26 -> 628 | S26: =C26*0.264 -> 461.472 | T26: =(C26-D26-E26)*0.264 -> 400.488 | U26: =R26/Q26 -> 0.80616175 | V26: =(C26-D26-E26)/C26 -> 0.86784897 | W26: =S26/R26 -> 0.73482803 | X26: =U26*V26*W26 -> 0.51410526
A27: 26 | B27: P2 | C27: =Usinage!C27-Usinage!D27-Usinage!E27 -> 1690 | D27: 40 | E27: 177 | G27: 40 | H27: 5 | I27: 28 | J27: 21 | L27: 132 | N27: 8 | O27: =37500/250 -> 150 | P27: =4000*60/250 -> 960 | Q27: =P27-H27-J27-M27-N27-O27 -> 776 | R27: =Q27-F27-G27-I27-K27-L27 -> 576 | S27: =C27*0.264 -> 446.16 | T27: =(C27-D27-E27)*0.264 -> 388.872 | U27: =R27/Q27 -> 0.74226804 | V27: =(C27-D27-E27)/C27 -> 0.87159763 | W27: =S27/R27 -> 0.77458333 | X27: =U27*V27*W27 -> 0.50112371
A28: 27 | B28: P4 | C28: =Usinage!C28-Usinage!D28-Usinage!E28 -> 1580 | D28: 57 | E28: 161 | G28: 45 | H28: 9 | I28: 20 | J28: 24 | L28: 135 | O28: =37500/250 -> 150 | P28: =4000*60/250 -> 960 | Q28: =P28-H28-J28-M28-N28-O28 -> 777 | R28: =Q28-F28-G28-I28-K28-L28 -> 577 | S28: =C28*0.264 -> 417.12 | T28: =(C28-D28-E28)*0.264 -> 359.568 | U28: =R28/Q28 -> 0.74259974 | V28: =(C28-D28-E28)/C28 -> 0.86202532 | W28: =S28/R28 -> 0.72291161 | X28: =U28*V28*W28 -> 0.46276448
A29: 28 | B29: P4 | C29: =Usinage!C29-Usinage!D29-Usinage!E29 -> 1611 | D29: 47 | E29: 145 | G29: 22 | H29: 6 | I29: 27 | J29: 22 | L29: 112 | O29: =37500/250 -> 150 | P29: =4000*60/250 -> 960 | Q29: =P29-H29-J29-M29-N29-O29 -> 782 | R29: =Q29-F29-G29-I29-K29-L29 -> 621 | S29: =C29*0.264 -> 425.304 | T29: =(C29-D29-E29)*0.264 -> 374.616 | U29: =R29/Q29 -> 0.79411765 | V29: =(C29-D29-E29)/C29 -> 0.88081937 | W29: =S29/R29 -> 0.68486957 | X29: =U29*V29*W29 -> 0.47904859
A30: 29 | B30: P3 | C30: =Usinage!C30-Usinage!D30-Usinage!E30 -> 1723 | D30: 43 | E30: 144 | G30: 33 | H30: 10 | I30: 25 | J30: 22 | L30: 110 | O30: =37500/250 -> 150 | P30: =4000*60/250 -> 960 | Q30: =P30-H30-J30-M30-N30-O30 -> 778 | R30: =Q30-F30-G30-I30-K30-L30 -> 610 | S30: =C30*0.264 -> 454.872 | T30: =(C30-D30-E30)*0.264 -> 405.504 | U30: =R30/Q30 -> 0.7840617 | V30: =(C30-D30-E30)/C30 -> 0.89146837 | W30: =S30/R30 -> 0.7456918 | X30: =U30*V30*W30 -> 0.52121337
A31: 30 | B31: P2 | C31: =Usinage!C31-Usinage!D31-Usinage!E31 -> 1742 | D31: 50 | E31: 162 | G31: 27 | H31: 5 | I31: 25 | J31: 23 | L31: 140 | N31: 10 | O31: =37500/250 -> 150 | P31: =4000*60/250 -> 960 | Q31: =P31-H31-J31-M31-N31-O31 -> 772 | R31: =Q31-F31-G31-I31-K31-L31 -> 580 | S31: =C31*0.264 -> 459.888 | T31: =(C31-D31-E31)*0.264 -> 403.92 | U31: =R31/Q31 -> 0.75129534 | V31: =(C31-D31-E31)/C31 -> 0.8783008 | W31: =S31/R31 -> 0.79291034 | X31: =U31*V31*W31 -> 0.52321244
A32: 31 | B32: P1 | C32: =Usinage!C32-Usinage!D32-Usinage!E32 -> 1700 | D32: 54 | E32: 141 | G32: 25 | H32: 9 | I32: 23 | J32: 24 | L32: 107 | O32: =37500/250 -> 150 | P32: =4000*60/250 -> 960 | Q32: =P32-H32-J32-M32-N32-O32 -> 777 | R32: =Q32-F32-G32-I32-K32-L32 -> 622 | S32: =C32*0.264 -> 448.8 | T32: =(C32-D32-E32)*0.264 -> 397.32 | U32: =R32/Q32 -> 0.8005148 | V32: =(C32-D32-E32)/C32 -> 0.88529412 | W32: =S32/R32 -> 0.72154341 | X32: =U32*V32*W32 -> 0.51135135
A33: 32 | B33: P3 | C33: =Usinage!C33-Usinage!D33-Usinage!E33 -> 1616 | D33: 41 | E33: 171 | G33: 54 | H33: 8 | I33: 28 | J33: 25 | L33: 109 | O33: =37500/250 -> 150 | P33: =4000*60/250 -> 960 | Q33: =P33-H33-J33-M33-N33-O33 -> 777 | R33: =Q33-F33-G33-I33-K33-L33 -> 586 | S33: =C33*0.264 -> 426.624 | T33: =(C33-D33-E33)*0.264 -> 370.656 | U33: =R33/Q33 -> 0.75418275 | V33: =(C33-D33-E33)/C33 -> 0.86881188 | W33: =S33/R33 -> 0.7280273 | X33: =U33*V33*W33 -> 0.47703475
A34: 33 | B34: P2 | C34: =Usinage!C34-Usinage!D34-Usinage!E34 -> 1624 | D34: 58 | E34: 143 | G34: 49 | H34: 7 | I34: 30 | J34: 25 | L34: 113 | O34: =37500/250 -> 150 | P34: =4000*60/250 -> 960 | Q34: =P34-H34-J34-M34-N34-O34 -> 778 | R34: =Q34-F34-G34-I34-K34-L34 -> 586 | S34: =C34*0.264 -> 428.736 | T34: =(C34-D34-E34)*0.264 -> 375.672 | U34: =R34/Q34 -> 0.75321337 | V34: =(C34-D34-E34)/C34 -> 0.87623153 | W34: =S34/R34 -> 0.7316314 | X34: =U34*V34*W34 -> 0.48286889
A35: 34 | B35: P2 | C35: =Usinage!C35-Usinage!D35-Usinage!E35 -> 1539 | D35: 57 | E35: 185 | G35: 30 | H35: 5 | I35: 29 | J35: 24 | L35: 131 | N35: 10 | O35: =37500/250 -> 150 | P35: =4000*60/250 -> 960 | Q35: =P35-H35-J35-M35-N35-O35 -> 771 | R35: =Q35-F35-G35-I35-K35-L35 -> 581 | S35: =C35*0.264 -> 406.296 | T35: =(C35-D35-E35)*0.264 -> 342.408 | U35: =R35/Q35 -> 0.7535668 | V35: =(C35-D35-E35)/C35 -> 0.84275504 | W35: =S35/R35 -> 0.69930465 | X35: =U35*V35*W35 -> 0.44410895
A36: 35 | B36: P4 | C36: =Usinage!C36-Usinage!D36-Usinage!E36 -> 1591 | D36: 52 | E36: 171 | G36: 41 | H36: 7 | I36: 27 | J36: 20 | L36: 119 | O36: =37500/250 -> 150 | P36: =4000*60/250 -> 960 | Q36: =P36-H36-J36-M36-N36-O36 -> 783 | R36: =Q36-F36-G36-I36-K36-L36 -> 596 | S36: =C36*0.264 -> 420.024 | T36: =(C36-D36-E36)*0.264 -> 361.152 | U36: =R36/Q36 -> 0.76117497 | V36: =(C36-D36-E36)/C36 -> 0.85983658 | W36: =S36/R36 -> 0.70473826 | X36: =U36*V36*W36 -> 0.46124138
A37: 36 | B37: P3 | C37: =Usinage!C37-Usinage!D37-Usinage!E37 -> 1613 | D37: 56 | E37: 177 | G37: 43 | H37: 7 | I37: 20 | J37: 20 | L37: 126 | O37: =37500/250 -> 150 | P37: =4000*60/250 -> 960 | Q37: =P37-H37-J37-M37-N37-O37 -> 783 | R37: =Q37-F37-G37-I37-K37-L37 -> 594 | S37: =C37*0.264 -> 425.832 | T37: =(C37-D37-E37)*0.264 -> 364.32 | U37: =R37/Q37 -> 0.75862069 | V37: =(C37-D37-E37)/C37 -> 0.85554867 | W37: =S37/R37 -> 0.71688889 | X37: =U37*V37*W37 -> 0.46528736
A38: 37 | B38: P2 | C38: =Usinage!C38-Usinage!D38-Usinage!E38 -> 1580 | D38: 41 | E38: 175 | G38: 39 | H38: 6 | I38: 25 | J38: 21 | L38: 114 | O38: =37500/250 -> 150 | P38: =4000*60/250 -> 960 | Q38: =P38-H38-J38-M38-N38-O38 -> 783 | R38: =Q38-F38-G38-I38-K38-L38 -> 605 | S38: =C38*0.264 -> 417.12 | T38: =(C38-D38-E38)*0.264 -> 360.096 | U38: =R38/Q38 -> 0.77266922 | V38: =(C38-D38-E38)/C38 -> 0.86329114 | W38: =S38/R38 -> 0.68945455 | X38: =U38*V38*W38 -> 0.45989272
A39: 38 | B39: P1 | C39: =Usinage!C39-Usinage!D39-Usinage!E39 -> 1660 | D39: 54 | E39: 159 | G39: 35 | H39: 5 | I39: 23 | J39: 25 | L39: 124 | N39: 9 | O39: =37500/250 -> 150 | P39: =4000*60/250 -> 960 | Q39: =P39-H39-J39-M39-N39-O39 -> 771 | R39: =Q39-F39-G39-I39-K39-L39 -> 589 | S39: =C39*0.264 -> 438.24 | T39: =(C39-D39-E39)*0.264 -> 382.008 | U39: =R39/Q39 -> 0.76394293 | V39: =(C39-D39-E39)/C39 -> 0.87168675 | W39: =S39/R39 -> 0.74404075 | X39: =U39*V39*W39 -> 0.49547082
A40: 39 | B40: P3 | C40: =Usinage!C40-Usinage!D40-Usinage!E40 -> 1692 | D40: 59 | E40: 134 | G40: 31 | H40: 6 | I40: 28 | J40: 20 | L40: 98 | O40: =37500/250 -> 150 | P40: =4000*60/250 -> 960 | Q40: =P40-H40-J40-M40-N40-O40 -> 784 | R40: =Q40-F40-G40-I40-K40-L40 -> 627 | S40: =C40*0.264 -> 446.688 | T40: =(C40-D40-E40)*0.264 -> 395.736 | U40: =R40/Q40 -> 0.7997449 | V40: =(C40-D40-E40)/C40 -> 0.88593381 | W40: =S40/R40 -> 0.71242105 | X40: =U40*V40*W40 -> 0.50476531
...
